<?xml version="1.0" ?>
<!-- =================================================================================== -->
<!-- |    This document was autogenerated by xacro from irb140.xacro                   | -->
<!-- |    EDITING THIS FILE BY HAND IS NOT RECOMMENDED                                 | -->
<!-- =================================================================================== -->
<robot name="abb_irb140" xmlns:xacro="http://ros.org/wiki/xacro">
    <!-- link list -->
    <link name="base_link">
        <visual>
            <origin rpy="0 0 0" xyz="0 0 0" />
            <geometry>
                <mesh filename="package://abb_irb140_support/meshes/irb140/visual/base_link.stl" scale="0.01 0.01 0.01" />
            </geometry>
            <material name="abb_orange">
                <color rgba="1 0.43 0 1" />
            </material>
        </visual>
        <collision>
            <geometry>
                <mesh filename="package://abb_irb140_support/meshes/irb140/collision/base_link.stl" scale="0.01 0.01 0.01" />
            </geometry>
            <material name="yellow">
                <color rgba="0 1 1 1" />
            </material>
        </collision>
        <inertial>
            <mass value="0.1" />
            <origin xyz="0 0 0" rpy="0 0 0" />
            <inertia ixx="0.03" iyy="0.03" izz="0.03" ixy="0.0" ixz="0.0" iyz="0.0" />
        </inertial>
    </link>
    <link name="link_1">
        <visual>
            <origin rpy="0 0 0" xyz="0 0 0" />
            <geometry>
                <mesh filename="package://abb_irb140_support/meshes/irb140/visual/link_1.stl" scale="0.01 0.01 0.01" />
            </geometry>
            <material name="abb_orange" />
        </visual>
        <collision>
            <origin rpy="0 0 0" xyz="0 0 0" />
            <geometry>
                <mesh filename="package://abb_irb140_support/meshes/irb140/collision/link_1.stl" scale="0.01 0.01 0.01" />
            </geometry>
            <material name="yellow" />
        </collision>
        <inertial>
            <mass value="0.1" />
            <origin xyz="0 0 0" rpy="0 0 0" />
            <inertia ixx="0.03" iyy="0.03" izz="0.03" ixy="0.0" ixz="0.0" iyz="0.0" />
        </inertial>
    </link>
    <link name="link_2">
        <visual>
            <origin rpy="0 0 0" xyz="-0.07 0 -0.352" />
            <geometry>
                <mesh filename="package://abb_irb140_support/meshes/irb140/visual/link_2.stl" scale="0.01 0.01 0.01" />
            </geometry>
            <material name="abb_orange" />
        </visual>
        <collision>
            <origin rpy="0 0 0" xyz="-0.07 0 -0.352" />
            <geometry>
                <mesh filename="package://abb_irb140_support/meshes/irb140/collision/link_2.stl" scale="0.01 0.01 0.01" />
            </geometry>
            <material name="yellow" />
        </collision>
        <inertial>
            <mass value="0.1" />
            <origin xyz="0 0 0" rpy="0 0 0" />
            <inertia ixx="0.03" iyy="0.03" izz="0.03" ixy="0.0" ixz="0.0" iyz="0.0" />
        </inertial>
    </link>
    <link name="link_3">
        <visual>
            <origin rpy="0 0 0" xyz="-0.07 0.065 -0.712" />
            <geometry>
                <mesh filename="package://abb_irb140_support/meshes/irb140/visual/link_3.stl" scale="0.01 0.01 0.01" />
            </geometry>
            <material name="abb_orange" />
        </visual>
        <collision>
            <origin rpy="0 0 0" xyz="-0.07 0.065 -0.712" />
            <geometry>
                <mesh filename="package://abb_irb140_support/meshes/irb140/collision/link_3.stl" scale="0.01 0.01 0.01" />
            </geometry>
            <material name="yellow" />
        </collision>
        <inertial>
            <mass value="0.1" />
            <origin xyz="0 0 0" rpy="0 0 0" />
            <inertia ixx="0.03" iyy="0.03" izz="0.03" ixy="0.0" ixz="0.0" iyz="0.0" />
        </inertial>
    </link>
    <link name="link_4">
        <visual>
            <origin rpy="0 0 0" xyz="-0.309 0 -0.712" />
            <geometry>
                <mesh filename="package://abb_irb140_support/meshes/irb140/visual/link_4.stl" scale="0.01 0.01 0.01" />
            </geometry>
            <material name="abb_orange" />
        </visual>
        <collision>
            <origin rpy="0 0 0" xyz="-0.309 0 -0.712" />
            <geometry>
                <mesh filename="package://abb_irb140_support/meshes/irb140/collision/link_4.stl" scale="0.01 0.01 0.01" />
            </geometry>
            <material name="yellow" />
        </collision>
        <inertial>
            <mass value="0.1" />
            <origin xyz="0 0 0" rpy="0 0 0" />
            <inertia ixx="0.03" iyy="0.03" izz="0.03" ixy="0.0" ixz="0.0" iyz="0.0" />
        </inertial>
    </link>
    <link name="link_5">
        <visual>
            <origin rpy="0 0 0" xyz="-0.450 0 -0.712" />
            <geometry>
                <mesh filename="package://abb_irb140_support/meshes/irb140/visual/link_5.stl" scale="0.01 0.01 0.01" />
            </geometry>
            <material name="abb_orange" />
        </visual>
        <collision>
            <origin rpy="0 0 0" xyz="-0.450 0 -0.712" />
            <geometry>
                <mesh filename="package://abb_irb140_support/meshes/irb140/collision/link_5.stl" scale="0.01 0.01 0.01" />
            </geometry>
            <material name="yellow" />
        </collision>
        <inertial>
            <mass value="0.1" />
            <origin xyz="0 0 0" rpy="0 0 0" />
            <inertia ixx="0.03" iyy="0.03" izz="0.03" ixy="0.0" ixz="0.0" iyz="0.0" />
        </inertial>
    </link>
    <link name="link_6">
        <visual>
            <origin rpy="0 0 0" xyz="-0.515 0 -0.712" />
            <geometry>
                <mesh filename="package://abb_irb140_support/meshes/irb140/visual/link_6.stl" scale="0.01 0.01 0.01" />
            </geometry>
            <material name="abb_orange" />
        </visual>
        <collision>
            <origin rpy="0 0 0" xyz="-0.515 0 -0.712" />
            <geometry>
                <mesh filename="package://abb_irb140_support/meshes/irb140/collision/link_6.stl" scale="0.01 0.01 0.01" />
            </geometry>
            <material name="yellow" />
        </collision>
        <inertial>
            <mass value="0.1" />
            <origin xyz="0 0 0" rpy="0 0 0" />
            <inertia ixx="0.03" iyy="0.03" izz="0.03" ixy="0.0" ixz="0.0" iyz="0.0" />
        </inertial>
    </link>
    <link name="tool0" />
    <!-- end of link list -->
    <!-- joint list -->
    <joint name="joint_1" type="revolute">
        <origin rpy="0 0 0" xyz="0 0 0" />
        <parent link="base_link" />
        <child link="link_1" />
        <axis xyz="0 0 1" />
        <limit effort="0" lower="-3.1416" upper="3.1416" velocity="3.4907" />
    </joint>
    <joint name="joint_2" type="revolute">
        <origin rpy="0 0 0" xyz="0.070 0 0.352" />
        <parent link="link_1" />
        <child link="link_2" />
        <axis xyz="0 1 0" />
        <limit effort="0" lower="-1.5708" upper="1.9199" velocity="3.4907" />
    </joint>
    <joint name="joint_3" type="revolute">
        <origin rpy="0 0 0" xyz="0 -0.065 0.360" />
        <parent link="link_2" />
        <child link="link_3" />
        <axis xyz="0 1 0" />
        <limit effort="0" lower="-4.0143" upper="0.87274434" velocity="4.5379" />
    </joint>
    <joint name="joint_4" type="revolute">
        <origin rpy="0 0 0" xyz="0.239 0.065 0" />
        <parent link="link_3" />
        <child link="link_4" />
        <axis xyz="1 0 0" />
        <limit effort="0" lower="-3.4907" upper="3.4907" velocity="6.2832" />
    </joint>
    <joint name="joint_5" type="revolute">
        <origin rpy="0 0 0" xyz="0.141 0 0" />
        <parent link="link_4" />
        <child link="link_5" />
        <axis xyz="0 1 0" />
        <limit effort="0" lower="-2.0071" upper="2.0071" velocity="6.2832" />
    </joint>
    <joint name="joint_6" type="revolute">
        <origin rpy="0 0 0" xyz="0.065 0 0" />
        <parent link="link_5" />
        <child link="link_6" />
        <axis xyz="1 0 0" />
        <limit effort="0" lower="-6.9813" upper="6.9813" velocity="7.854" />
    </joint>
    <joint name="joint_6-tool0" type="fixed">
        <parent link="link_6" />
        <child link="tool0" />
        <origin rpy="0 0 0" xyz="0 0 0" />
    </joint>
    <!-- end of joint list -->
    <!-- ROS base_link to ABB World Coordinates transform -->
    <link name="base" />
    <joint name="base_link-base" type="fixed">
        <origin rpy="0 0 0" xyz="0 0 0" />
        <parent link="base_link" />
        <child link="base" />
    </joint>
    <link name="obj_position_link">
        <visual>
            <origin rpy="0 1.5708 0" xyz="-0.125 0 0" />
            <geometry>
                <cylinder radius="0.21" length="0.25" />
            </geometry>
            <material name="blue" />
        </visual>
        <collision>
            <origin rpy="0 1.5708 0" xyz="-0.125 0 0" />
            <geometry>
                <cylinder radius="0.21" length="0.25" />
            </geometry>
            <material name="blue" />
        </collision>
        <inertial>
            <mass value="0.1" />
            <origin xyz="0 0 0" rpy="0 0 0" />
            <inertia ixx="0.03" iyy="0.03" izz="0.03" ixy="0.0" ixz="0.0" iyz="0.0" />
        </inertial>
    </link>
    <joint name="base_link-obj_position_link" type="fixed">
        <origin rpy="0 1.5708 0" xyz="0.5 0 0" />
        <parent link="base_link" />
        <child link="obj_position_link" />
    </joint>
    <transmission name="trans_joint_1">
        <type>transmission_interface/SimpleTransmission</type>
        <joint name="joint_1">
            <hardwareInterface>hardware_interface/EffortJointInterface</hardwareInterface>
        </joint>
        <actuator name="joint_1_motor">
            <hardwareInterface>hardware_interface/EffortJointInterface</hardwareInterface>
            <mechanicalReduction>1</mechanicalReduction>
        </actuator>
    </transmission>
    <transmission name="trans_joint_2">
        <type>transmission_interface/SimpleTransmission</type>
        <joint name="joint_2">
            <hardwareInterface>hardware_interface/EffortJointInterface</hardwareInterface>
        </joint>
        <actuator name="joint_2_motor">
            <hardwareInterface>hardware_interface/EffortJointInterface</hardwareInterface>
            <mechanicalReduction>1</mechanicalReduction>
        </actuator>
    </transmission>
    <transmission name="trans_joint_3">
        <type>transmission_interface/SimpleTransmission</type>
        <joint name="joint_3">
            <hardwareInterface>hardware_interface/EffortJointInterface</hardwareInterface>
        </joint>
        <actuator name="joint_3_motor">
            <hardwareInterface>hardware_interface/EffortJointInterface</hardwareInterface>
            <mechanicalReduction>1</mechanicalReduction>
        </actuator>
    </transmission>
    <transmission name="trans_joint_4">
        <type>transmission_interface/SimpleTransmission</type>
        <joint name="joint_4">
            <hardwareInterface>hardware_interface/EffortJointInterface</hardwareInterface>
        </joint>
        <actuator name="joint_4_motor">
            <hardwareInterface>hardware_interface/EffortJointInterface</hardwareInterface>
            <mechanicalReduction>1</mechanicalReduction>
        </actuator>
    </transmission>
    <transmission name="trans_joint_5">
        <type>transmission_interface/SimpleTransmission</type>
        <joint name="joint_5">
            <hardwareInterface>hardware_interface/EffortJointInterface</hardwareInterface>
        </joint>
        <actuator name="joint_5_motor">
            <hardwareInterface>hardware_interface/EffortJointInterface</hardwareInterface>
            <mechanicalReduction>1</mechanicalReduction>
        </actuator>
    </transmission>
    <transmission name="trans_joint_6">
        <type>transmission_interface/SimpleTransmission</type>
        <joint name="joint_6">
            <hardwareInterface>hardware_interface/EffortJointInterface</hardwareInterface>
        </joint>
        <actuator name="joint_6_motor">
            <hardwareInterface>hardware_interface/EffortJointInterface</hardwareInterface>
            <mechanicalReduction>1</mechanicalReduction>
        </actuator>
    </transmission>
    <gazebo>
        <plugin name="gazebo_ros_control">
            <robotNamespace>/</robotNamespace>
        </plugin>
    </gazebo>
</robot>

